I'm sorry, but an uncaught exception occurred.

While running game code:
  File "game/scripts/actTwo.rpy", line 12, in script
    "[DEBUG: Intro]"
KeyError: 'DEBUG'

-- Full Traceback ------------------------------------------------------------

Full traceback:
  File "game/scripts/actTwo.rpy", line 12, in script
    "[DEBUG: Intro]"
  File "D:\Ren'Py\renpy-7.4.9-sdk\renpy\ast.py", line 921, in execute
    renpy.exports.say(who, what, *args, **kwargs)
  File "D:\Ren'Py\renpy-7.4.9-sdk\renpy\exports.py", line 1373, in say
    who(what, *args, **kwargs)
  File "D:\Ren'Py\renpy-7.4.9-sdk\renpy\character.py", line 1253, in __call__
    what = self.prefix_suffix("what", self.what_prefix, what, self.what_suffix)
  File "D:\Ren'Py\renpy-7.4.9-sdk\renpy\character.py", line 1172, in prefix_suffix
    return (sub(prefix) + sub(body) + sub(suffix))
  File "D:\Ren'Py\renpy-7.4.9-sdk\renpy\character.py", line 1152, in sub
    return renpy.substitutions.substitute(s, scope=scope, force=force, translate=translate)[0]
  File "D:\Ren'Py\renpy-7.4.9-sdk\renpy\substitutions.py", line 278, in substitute
    s = formatter.vformat(s, (), kwargs) # type: ignore
  File "/home/tom/ab/renpy-build/tmp/install.linux-x86_64/lib/python3.9/string.py", line 165, in vformat
  File "/home/tom/ab/renpy-build/tmp/install.linux-x86_64/lib/python3.9/string.py", line 205, in _vformat
  File "D:\Ren'Py\renpy-7.4.9-sdk\renpy\substitutions.py", line 168, in get_field
    obj, arg_used = super(Formatter, self).get_field(field_name, args, kwargs)
  File "/home/tom/ab/renpy-build/tmp/install.linux-x86_64/lib/python3.9/string.py", line 270, in get_field
  File "/home/tom/ab/renpy-build/tmp/install.linux-x86_64/lib/python3.9/string.py", line 227, in get_value
KeyError: 'DEBUG'

Windows-10-10.0.19044 AMD64
Ren'Py 8.0.2.22081402
Project Avadakadabra v0.0.1
Tue Sep 13 23:07:15 2022
